<?xml version="1.0" ?>
<!-- =================================================================================== -->
<!-- |    This document was autogenerated by xacro from ./shark_v1.xacro               | -->
<!-- |    EDITING THIS FILE BY HAND IS NOT RECOMMENDED                                 | -->
<!-- =================================================================================== -->
<robot name="shark-v1">
  <!-- Measured from CAD file -->
  <link name="head_link">
    <inertial>
      <origin rpy="0 0 0" xyz="0 0 0"/>
      <mass value="0.001"/>
      <inertia ixx="0.001" ixy="0" ixz="0" iyy="0.001" iyz="0" izz="0.001"/>
    </inertial>
    <visual name="head">
      <origin rpy="1.5708 0 0" xyz="-0.02248 -0.11374 -0.02141"/>
      <geometry>
        <mesh filename="package://doris_head_description/meshes/dae/Cube.001.dae" scale="0.001 0.001 0.001"/>
      </geometry>
      <material name="Gray_001"/>
    </visual>
  </link>
  <link name="jaw_link">
    <inertial>
      <origin rpy="0 0 0" xyz="0 0 0"/>
      <mass value="0.001"/>
      <inertia ixx="0.001" ixy="0" ixz="0" iyy="0.001" iyz="0" izz="0.001"/>
    </inertial>
    <visual name="jaw">
      <origin rpy="1.5708 0 0" xyz="0.05463 0.06043 -0.08008"/>
      <geometry>
        <mesh filename="package://doris_head_description/meshes/dae/Plane.012.dae" scale="0.001 0.001 0.001"/>
      </geometry>
      <material name="Face_000"/>
    </visual>
  </link>
  <link name="left_eye_horizontal_link">
    <inertial>
      <origin rpy="0 0 0" xyz="0 0 0"/>
      <mass value="0.001"/>
      <inertia ixx="0.001" ixy="0" ixz="0" iyy="0.001" iyz="0" izz="0.001"/>
    </inertial>
  </link>
  <link name="left_eye_vertical_link">
    <inertial>
      <origin rpy="0 0 0" xyz="0 0 0"/>
      <mass value="0.001"/>
      <inertia ixx="0.001" ixy="0" ixz="0" iyy="0.001" iyz="0" izz="0.001"/>
    </inertial>
    <visual name="left_eye">
      <origin rpy="-1.5708 0 0" xyz="0 0 0"/>
      <geometry>
        <mesh filename="package://doris_head_description/meshes/dae/Cube.002.dae" scale="0.001 0.001 0.001"/>
      </geometry>
      <material name="WHITE_003"/>
    </visual>
  </link>
  <link name="left_inferior_eyelid_link">
    <inertial>
      <origin rpy="0 0 0" xyz="0 0 0"/>
      <mass value="0.001"/>
      <inertia ixx="0.001" ixy="0" ixz="0" iyy="0.001" iyz="0" izz="0.001"/>
    </inertial>
    <visual name="left_inferior_eyelid">
      <origin rpy="-1.56706 -0.06102 -0.06125" xyz="0.00498 -0.01247 -0.02356"/>
      <geometry>
        <mesh filename="package://doris_head_description/meshes/dae/Plane.015.dae" scale="0.001 0.001 0.001"/>
      </geometry>
      <material name="Gray_001"/>
    </visual>
  </link>
  <link name="left_rotacional_eyebrow_link">
    <inertial>
      <origin rpy="0 0 0" xyz="0 0 0"/>
      <mass value="0.001"/>
      <inertia ixx="0.001" ixy="0" ixz="0" iyy="0.001" iyz="0" izz="0.001"/>
    </inertial>
    <visual name="left_eyebrow">
      <origin rpy="0 0 0" xyz="0 0 0"/>
      <geometry>
        <mesh filename="package://doris_head_description/meshes/dae/Cylinder.004.dae" scale="0.001 0.001 0.001"/>
      </geometry>
      <material name="BLACK_006"/>
    </visual>
  </link>
  <link name="left_superior_eyelid_link">
    <inertial>
      <origin rpy="0 0 0" xyz="0 0 0"/>
      <mass value="0.001"/>
      <inertia ixx="0.001" ixy="0" ixz="0" iyy="0.001" iyz="0" izz="0.001"/>
    </inertial>
    <visual name="left_superior_eyelid">
      <origin rpy="1.5708 -0.06113 0" xyz="0.00551 -0.01216 -0.01543"/>
      <geometry>
        <mesh filename="package://doris_head_description/meshes/dae/Plane.001.dae" scale="0.001 0.001 0.001"/>
      </geometry>
      <material name="Gray_001"/>
    </visual>
  </link>
  <link name="left_vertical_eyebrow_link">
    <inertial>
      <origin rpy="0 0 0" xyz="0 0 0"/>
      <mass value="0.001"/>
      <inertia ixx="0.001" ixy="0" ixz="0" iyy="0.001" iyz="0" izz="0.001"/>
    </inertial>
  </link>
  <link name="neck_link">
    <inertial>
      <origin rpy="0 0 0" xyz="0 0 0"/>
      <mass value="0.001"/>
      <inertia ixx="0.001" ixy="0" ixz="0" iyy="0.001" iyz="0" izz="0.001"/>
    </inertial>
    <visual name="neck">
      <origin rpy="0 0 0" xyz="0 0 0"/>
      <geometry>
        <mesh filename="package://doris_head_description/meshes/dae/Cube.055.dae" scale="0.01 0.01 0.01"/>
      </geometry>
    </visual>
  </link>
  <link name="right_rotacional_eyebrow_link">
    <inertial>
      <origin rpy="0 0 0" xyz="0 0 0"/>
      <mass value="0.001"/>
      <inertia ixx="0.001" ixy="0" ixz="0" iyy="0.001" iyz="0" izz="0.001"/>
    </inertial>
    <visual name="right_eyebrow">
      <origin rpy="0 0 0" xyz="0 0 0"/>
      <geometry>
        <mesh filename="package://doris_head_description/meshes/dae/Cylinder.005.dae" scale="0.001 0.001 0.001"/>
      </geometry>
      <material name="BLACK_007"/>
    </visual>
  </link>
  <link name="right_vertical_eyebrow_link">
    <inertial>
      <origin rpy="0 0 0" xyz="0 0 0"/>
      <mass value="0.001"/>
      <inertia ixx="0.001" ixy="0" ixz="0" iyy="0.001" iyz="0" izz="0.001"/>
    </inertial>
  </link>
  <link name="right_eye_horizontal_link">
    <inertial>
      <origin rpy="0 0 0" xyz="0 0 0"/>
      <mass value="0.001"/>
      <inertia ixx="0.001" ixy="0" ixz="0" iyy="0.001" iyz="0" izz="0.001"/>
    </inertial>
  </link>
  <link name="right_eye_vertical_link">
    <inertial>
      <origin rpy="0 0 0" xyz="0 0 0"/>
      <mass value="0.001"/>
      <inertia ixx="0.001" ixy="0" ixz="0" iyy="0.001" iyz="0" izz="0.001"/>
    </inertial>
    <visual name="right_eye">
      <origin rpy="-1.5708 0 0" xyz="0 0 0"/>
      <geometry>
        <mesh filename="package://doris_head_description/meshes/dae/Cube.007.dae" scale="0.001 0.001 0.001"/>
      </geometry>
      <material name="WHITE_004"/>
    </visual>
  </link>
  <link name="right_inferior_eyelid_link">
    <inertial>
      <origin rpy="0 0 0" xyz="0 0 0"/>
      <mass value="0.001"/>
      <inertia ixx="0.001" ixy="0" ixz="0" iyy="0.001" iyz="0" izz="0.001"/>
    </inertial>
    <visual name="right_inferior_eyelid">
      <origin rpy="-1.5708 0 0" xyz="0.0038 -0.01141 -0.01966"/>
      <geometry>
        <mesh filename="package://doris_head_description/meshes/dae/Plane.013.dae" scale="0.001 0.001 0.001"/>
      </geometry>
      <material name="Gray_001"/>
    </visual>
  </link>
  <link name="right_superior_eyelid_link">
    <inertial>
      <origin rpy="0 0 0" xyz="0 0 0"/>
      <mass value="0.001"/>
      <inertia ixx="0.001" ixy="0" ixz="0" iyy="0.001" iyz="0" izz="0.001"/>
    </inertial>
    <visual name="right_superior_eyelid">
      <origin rpy="1.5708 0 0.3358" xyz="0.00701 -0.01106 -0.01469"/>
      <geometry>
        <mesh filename="package://doris_head_description/meshes/dae/Plane.014.dae" scale="0.001 0.001 0.001"/>
      </geometry>
      <material name="Gray_001"/>
    </visual>
  </link>
  <link name="head_root">
    <inertial>
      <origin rpy="0 0 0" xyz="0 0 0"/>
      <mass value="0.001"/>
      <inertia ixx="0.001" ixy="0" ixz="0" iyy="0.001" iyz="0" izz="0.001"/>
    </inertial>
  </link>
  <joint name="horizontal_neck_joint" type="revolute">
    <origin rpy="0 0 1.5708" xyz="0 0 0"/>
    <parent link="head_root"/>
    <child link="neck_link"/>
    <axis xyz="0 0 1.0"/>
    <limit effort="1.0" lower="-0.86" upper="0.86" velocity="10"/>
  </joint>
  <joint name="jaw_joint" type="revolute">
    <origin rpy="0 0 0" xyz="0.00668 -0.10888 0.05845"/>
    <parent link="head_link"/>
    <child link="jaw_link"/>
    <axis xyz="0 0 1.0"/>
    <limit effort="1.0" lower="0" upper="0.5" velocity="10"/>
  </joint>
  <joint name="left_eye_horizontal_joint" type="revolute">
    <origin rpy="1.5708 0 0" xyz="0.09352 -0.08739 -0.05892"/>
    <parent link="head_link"/>
    <child link="left_eye_horizontal_link"/>
    <axis xyz="0 0 1.0"/>
    <limit effort="1.0" lower="-0.27453" upper="0.7854" velocity="10"/>
  </joint>
  <joint name="left_eye_vertical_joint" type="revolute">
    <origin rpy="1.5708 0 0" xyz="0 0 0"/>
    <parent link="left_eye_horizontal_link"/>
    <child link="left_eye_vertical_link"/>
    <axis xyz="0 0 1.0"/>
    <limit effort="1.0" lower="-0.17453" upper="0.7854" velocity="10"/>
  </joint>
  <joint name="left_inferior_eyelid_joint" type="revolute">
    <origin rpy="-3.14159 -0.06113 0" xyz="0.09208 -0.08718 -0.0824"/>
    <parent link="head_link"/>
    <child link="left_inferior_eyelid_link"/>
    <axis xyz="0 0 1.0"/>
    <limit effort="1.0" lower="-0.17453" upper="0.7854" velocity="10"/>
  </joint>
  <joint name="left_rotacional_eyebrow_joint" type="revolute">
    <origin rpy="2e-05 1.57091 6e-05" xyz="0 0 0"/>
    <parent link="left_vertical_eyebrow_link"/>
    <child link="left_rotacional_eyebrow_link"/>
    <axis xyz="0 0 1.0"/>
    <limit effort="1.0" lower="-0.17453" upper="0.4" velocity="10"/>
  </joint>
  <joint name="left_superior_eyelid_joint" type="revolute">
    <origin rpy="0 0.06113 0" xyz="0.09123 -0.0871 -0.04284"/>
    <parent link="head_link"/>
    <child link="left_superior_eyelid_link"/>
    <axis xyz="0 0 1.0"/>
    <limit effort="1.0" lower="-0.17453" upper="0.4" velocity="10"/>
  </joint>
  <joint name="left_vertical_eyebrow_joint" type="prismatic">
    <origin rpy="1.5708 0 -0.00012" xyz="0.1119 -0.12427 -0.0587"/>
    <parent link="head_link"/>
    <child link="left_vertical_eyebrow_link"/>
    <axis xyz="0 0 1.0"/>
    <limit effort="1.0" lower="0" upper="0.02" velocity="10"/>
  </joint>
  <joint name="right_rotacional_eyebrow_joint" type="revolute">
    <origin rpy="0 1.5708 0" xyz="0 0 0"/>
    <parent link="right_vertical_eyebrow_link"/>
    <child link="right_rotacional_eyebrow_link"/>
    <axis xyz="0 0 1.0"/>
    <limit effort="1.0" lower="-0.4" upper="0.17453" velocity="10"/>
  </joint>
  <joint name="right_vertical_eyebrow_joint" type="prismatic">
    <origin rpy="1.5708 0 0" xyz="0.1119 -0.12289 0.01565"/>
    <parent link="head_link"/>
    <child link="right_vertical_eyebrow_link"/>
    <axis xyz="0 0 1.0"/>
    <limit effort="1.0" lower="0" upper="0.02" velocity="10"/>
  </joint>
  <joint name="right_eye_horizontal_joint" type="revolute">
    <origin rpy="1.5708 0 0" xyz="0.09352 -0.08739 0.01605"/>
    <parent link="head_link"/>
    <child link="right_eye_horizontal_link"/>
    <axis xyz="0 0 1.0"/>
    <limit effort="1.0" lower="-0.27453" upper="0.4" velocity="10"/>
  </joint>
  <joint name="right_eye_vertical_joint" type="revolute">
    <origin rpy="1.5708 0 0" xyz="0 0 0"/>
    <parent link="right_eye_horizontal_link"/>
    <child link="right_eye_vertical_link"/>
    <axis xyz="0 0 1.0"/>
    <limit effort="1.0" lower="-0.2" upper="0.7854" velocity="10"/>
  </joint>
  <joint name="right_inferior_eyelid_joint" type="revolute">
    <origin rpy="-3.14159 0 0" xyz="0.09188 -0.08649 -0.00398"/>
    <parent link="head_link"/>
    <child link="right_inferior_eyelid_link"/>
    <axis xyz="0 0 1.0"/>
    <limit effort="1.0" lower="-0.17" upper="0.7854" velocity="10"/>
  </joint>
  <joint name="right_superior_eyelid_joint" type="revolute">
    <origin rpy="0 0 0" xyz="0.09073 -0.08626 0.03037"/>
    <parent link="head_link"/>
    <child link="right_superior_eyelid_link"/>
    <axis xyz="0 0 1.0"/>
    <limit effort="1.0" lower="-0.4" upper="0.17" velocity="10"/>
  </joint>
  <joint name="vertical_neck_joint" type="revolute">
    <origin rpy="-1.5708 0 -1.5708" xyz="0.02367 -0.00121 0.01929"/>
    <parent link="neck_link"/>
    <child link="head_link"/>
    <axis xyz="0 0 1.0"/>
    <limit effort="1.0" lower="0" upper="0.5" velocity="10"/>
  </joint>
  <transmission name="tran1">
    <type>transmission_interface/SimpleTransmission</type>
    <joint name="horizontal_neck_joint">
      <hardwareInterface>hardware_interface/EffortJointInterface</hardwareInterface>
    </joint>
    <actuator name="motor1">
      <hardwareInterface>hardware_interface/EffortJointInterface</hardwareInterface>
      <mechanicalReduction>1</mechanicalReduction>
    </actuator>
  </transmission>
  <transmission name="tran2">
    <type>transmission_interface/SimpleTransmission</type>
    <joint name="vertical_neck_joint">
      <hardwareInterface>hardware_interface/EffortJointInterface</hardwareInterface>
    </joint>
    <actuator name="motor2">
      <hardwareInterface>hardware_interface/EffortJointInterface</hardwareInterface>
      <mechanicalReduction>1</mechanicalReduction>
    </actuator>
  </transmission>
  <transmission name="tran3">
    <type>transmission_interface/SimpleTransmission</type>
    <joint name="jaw_joint">
      <hardwareInterface>hardware_interface/EffortJointInterface</hardwareInterface>
    </joint>
    <actuator name="motor3">
      <hardwareInterface>hardware_interface/EffortJointInterface</hardwareInterface>
      <mechanicalReduction>1</mechanicalReduction>
    </actuator>
  </transmission>
  <transmission name="tran4">
    <type>transmission_interface/SimpleTransmission</type>
    <joint name="right_vertical_eyebrow_joint">
      <hardwareInterface>hardware_interface/EffortJointInterface</hardwareInterface>
    </joint>
    <actuator name="motor4">
      <hardwareInterface>hardware_interface/EffortJointInterface</hardwareInterface>
      <mechanicalReduction>1</mechanicalReduction>
    </actuator>
  </transmission>
  <transmission name="tran5">
    <type>transmission_interface/SimpleTransmission</type>
    <joint name="left_vertical_eyebrow_joint">
      <hardwareInterface>hardware_interface/EffortJointInterface</hardwareInterface>
    </joint>
    <actuator name="motor5">
      <hardwareInterface>hardware_interface/EffortJointInterface</hardwareInterface>
      <mechanicalReduction>1</mechanicalReduction>
    </actuator>
  </transmission>
  <transmission name="tran6">
    <type>transmission_interface/SimpleTransmission</type>
    <joint name="right_rotacional_eyebrow_joint">
      <hardwareInterface>hardware_interface/EffortJointInterface</hardwareInterface>
    </joint>
    <actuator name="motor6">
      <hardwareInterface>hardware_interface/EffortJointInterface</hardwareInterface>
      <mechanicalReduction>1</mechanicalReduction>
    </actuator>
  </transmission>
  <transmission name="tran7">
    <type>transmission_interface/SimpleTransmission</type>
    <joint name="left_rotacional_eyebrow_joint">
      <hardwareInterface>hardware_interface/EffortJointInterface</hardwareInterface>
    </joint>
    <actuator name="motor7">
      <hardwareInterface>hardware_interface/EffortJointInterface</hardwareInterface>
      <mechanicalReduction>1</mechanicalReduction>
    </actuator>
  </transmission>
  <transmission name="tran8">
    <type>transmission_interface/SimpleTransmission</type>
    <joint name="right_superior_eyelid_joint">
      <hardwareInterface>hardware_interface/EffortJointInterface</hardwareInterface>
    </joint>
    <actuator name="motor8">
      <hardwareInterface>hardware_interface/EffortJointInterface</hardwareInterface>
      <mechanicalReduction>1</mechanicalReduction>
    </actuator>
  </transmission>
  <transmission name="tran9">
    <type>transmission_interface/SimpleTransmission</type>
    <joint name="left_superior_eyelid_joint">
      <hardwareInterface>hardware_interface/EffortJointInterface</hardwareInterface>
    </joint>
    <actuator name="motor9">
      <hardwareInterface>hardware_interface/EffortJointInterface</hardwareInterface>
      <mechanicalReduction>1</mechanicalReduction>
    </actuator>
  </transmission>
  <transmission name="tran10">
    <type>transmission_interface/SimpleTransmission</type>
    <joint name="right_inferior_eyelid_joint">
      <hardwareInterface>hardware_interface/EffortJointInterface</hardwareInterface>
    </joint>
    <actuator name="motor10">
      <hardwareInterface>hardware_interface/EffortJointInterface</hardwareInterface>
      <mechanicalReduction>1</mechanicalReduction>
    </actuator>
  </transmission>
  <transmission name="tran11">
    <type>transmission_interface/SimpleTransmission</type>
    <joint name="left_inferior_eyelid_joint">
      <hardwareInterface>hardware_interface/EffortJointInterface</hardwareInterface>
    </joint>
    <actuator name="motor11">
      <hardwareInterface>hardware_interface/EffortJointInterface</hardwareInterface>
      <mechanicalReduction>1</mechanicalReduction>
    </actuator>
  </transmission>
  <transmission name="tran12">
    <type>transmission_interface/SimpleTransmission</type>
    <joint name="right_eye_horizontal_joint">
      <hardwareInterface>hardware_interface/EffortJointInterface</hardwareInterface>
    </joint>
    <actuator name="motor12">
      <hardwareInterface>hardware_interface/EffortJointInterface</hardwareInterface>
      <mechanicalReduction>1</mechanicalReduction>
    </actuator>
  </transmission>
  <transmission name="tran13">
    <type>transmission_interface/SimpleTransmission</type>
    <joint name="left_eye_horizontal_joint">
      <hardwareInterface>hardware_interface/EffortJointInterface</hardwareInterface>
    </joint>
    <actuator name="motor13">
      <hardwareInterface>hardware_interface/EffortJointInterface</hardwareInterface>
      <mechanicalReduction>1</mechanicalReduction>
    </actuator>
  </transmission>
  <transmission name="tran14">
    <type>transmission_interface/SimpleTransmission</type>
    <joint name="right_eye_vertical_joint">
      <hardwareInterface>hardware_interface/EffortJointInterface</hardwareInterface>
    </joint>
    <actuator name="motor14">
      <hardwareInterface>hardware_interface/EffortJointInterface</hardwareInterface>
      <mechanicalReduction>1</mechanicalReduction>
    </actuator>
  </transmission>
  <transmission name="tran15">
    <type>transmission_interface/SimpleTransmission</type>
    <joint name="left_eye_vertical_joint">
      <hardwareInterface>hardware_interface/EffortJointInterface</hardwareInterface>
    </joint>
    <actuator name="motor15">
      <hardwareInterface>hardware_interface/EffortJointInterface</hardwareInterface>
      <mechanicalReduction>1</mechanicalReduction>
    </actuator>
  </transmission>
  <!--gazebo>
    <plugin name="gazebo_ros_control" filename="libgazebo_ros_control.so">
      <robotNamespace>/doris_head</robotNamespace>
    </plugin>
  </gazebo-->
  <material name="BLACK_006">
    <color rgba="0.00291 0.00291 0.00291 1.0"/>
  </material>
  <material name="BLACK_007">
    <color rgba="0.00291 0.00291 0.00291 1.0"/>
  </material>
  <material name="Face_000">
    <color rgba="0.10651 0.09584 0.11784 1.0"/>
  </material>
  <material name="Gray_001">
    <color rgba="0.24256 0.24256 0.24256 1.0"/>
  </material>
  <material name="WHITE_003">
    <color rgba="0.64 0.64 0.64 1.0"/>
  </material>
  <material name="WHITE_004">
    <color rgba="0.64 0.64 0.64 1.0"/>
  </material>
  <!-- <xacro:property name="caster_wheel_radius" value="0.0375"/>
  <xacro:property name="caster_wheel_joint_offset" value="0.12"/> -->
  <!--Gazebo Differential Drive Plugin-->
  <gazebo>
    <plugin filename="libgazebo_ros_control.so" name="gazebo_ros_control"/>
    <plugin filename="libgazebo_ros_diff_drive.so" name="differential_drive_controller">
      <alwaysOn>true</alwaysOn>
      <legacyMode>false</legacyMode>
      <updateRate>40</updateRate>
      <leftJoint>left_wheel_joint</leftJoint>
      <rightJoint>right_wheel_joint</rightJoint>
      <wheelSeparation>0.36</wheelSeparation>
      <wheelDiameter>0.2</wheelDiameter>
      <torque>200</torque>
      <commandTopic>cmd_vel</commandTopic>
      <odometryTopic>odom</odometryTopic>
      <odometryFrame>odom</odometryFrame>
      <robotBaseFrame>base_footprint</robotBaseFrame>
      <publishWheelTF>true</publishWheelTF>
    </plugin>
  </gazebo>
  <gazebo reference="camera_link">
    <sensor name="camera_sensor" type="depth">
      <update_rate>20</update_rate>
      <camera>
        <horizontal_fov>1.0471975511965976</horizontal_fov>
        <vertical_fov>1.0471975511965976</vertical_fov>
        <image>
          <format>B8G8R8</format>
          <width>640</width>
          <height>480</height>
        </image>
        <clip>
          <near>0.05</near>
          <far>3</far>
        </clip>
      </camera>
      <plugin filename="libgazebo_ros_control.so" name="gazebo_ros_control">
        <robotNamespace>/simple_model</robotNamespace>
      </plugin>
      <plugin filename="libgazebo_ros_openni_kinect.so" name="camera_controller">
        <imageTopicName>butia_vision/bvb/image_rgb</imageTopicName>
        <cameraInfoTopicName>butia_vision/bvb/camera_info</cameraInfoTopicName>
        <depthImageTopicName>butia_vision/bvb/image_depth</depthImageTopicName>
        <depthImageCameraInfoTopicName>butia_vision/bvb/camera_info_depth</depthImageCameraInfoTopicName>
        <pointCloudTopicName>butia_vision/bvb/points</pointCloudTopicName>
        <frameName>camera_link</frameName>
        <robotNamespace>/</robotNamespace>
      </plugin>
      <transmission name="base_to_camera_trans">
        <type>transmission_interface/SimpleTransmission</type>
        <actuator name="motor1">
          <mechanicalReduction>1</mechanicalReduction>
        </actuator>
        <joint name="camera_joint">
          <hardwareInterface>EffortJointInterface</hardwareInterface>
        </joint>
      </transmission>
    </sensor>
  </gazebo>
  <material name="blue">
    <color rgba="0 0 0.8 1"/>
  </material>
  <material name="black">
    <color rgba="0 0 0 1"/>
  </material>
  <material name="darkgray">
    <color rgba="0.2 0.2 0.2 1"/>
  </material>
  <material name="lightgray">
    <color rgba="0.8 0.8 0.8 1"/>
  </material>
  <material name="white">
    <color rgba="1 1 1 1"/>
  </material>
  <material name="red">
    <color rgba="0.8 0.0 0.0 1.0"/>
  </material>
  <!-- Import Rviz colors -->
  <!--  <xacro:include filename="$(find ros_robotics)/urdf/materials.xacro" /> -->
  <link name="base_footprint">
    <!-- <xacro:box_inertia m="8" w="0.001" h="0.001" d="0.001" /> -->
    <visual>
      <origin rpy="0 0 0" xyz="0 0 0"/>
      <material name="white"/>
      <geometry>
        <box size="0.001 0.001 0.001"/>
      </geometry>
    </visual>
  </link>
  <link name="base_link">
    <inertial>
      <mass value="1"/>
      <inertia ixx="0.009360416666666668" ixy="0.0" ixz="0.0" iyy="0.030185416666666666" iyz="0.0" izz="0.020841666666666665"/>
    </inertial>
    <visual>
      <material name="lightgray"/>
      <geometry>
        <box size="0.5 0.335 0.235"/>
      </geometry>
    </visual>
    <collision>
      <geometry>
        <box size="0.5 0.335 0.235"/>
      </geometry>
    </collision>
  </link>
  <joint name="base_link_joint" type="fixed">
    <origin rpy="0 0 0" xyz="0 0 0.1875"/>
    <parent link="base_footprint"/>
    <child link="base_link"/>
  </joint>
  <link name="left_wheel">
    <visual>
      <material name="darkgray"/>
      <origin rpy="1.5707963267948966 0 0" xyz="0 0 0"/>
      <geometry>
        <cylinder length="0.05" radius="0.1"/>
      </geometry>
    </visual>
    <collision>
      <origin rpy="1.5707963267948966 0 0" xyz="0 0 0"/>
      <geometry>
        <cylinder length="0.05" radius="0.1"/>
      </geometry>
    </collision>
    <inertial>
      <mass value="10"/>
      <inertia ixx="0.027083333333333338" ixy="0" ixz="0" iyy="0.027083333333333338" iyz="0" izz="0.05"/>
    </inertial>
  </link>
  <joint name="left_wheel_joint" type="continuous">
    <axis rpy="0 0 0" xyz="0 1 0"/>
    <parent link="base_link"/>
    <child link="left_wheel"/>
    <origin rpy="0 0 0" xyz="0.0 0.1975 -0.0875"/>
  </joint>
  <link name="right_wheel">
    <visual>
      <material name="darkgray"/>
      <origin rpy="1.5707963267948966 0 0" xyz="0 0 0"/>
      <geometry>
        <cylinder length="0.05" radius="0.1"/>
      </geometry>
    </visual>
    <collision>
      <origin rpy="1.5707963267948966 0 0" xyz="0 0 0"/>
      <geometry>
        <cylinder length="0.05" radius="0.1"/>
      </geometry>
    </collision>
    <inertial>
      <mass value="10"/>
      <inertia ixx="0.027083333333333338" ixy="0" ixz="0" iyy="0.027083333333333338" iyz="0" izz="0.05"/>
    </inertial>
  </link>
  <joint name="right_wheel_joint" type="continuous">
    <axis rpy="0 0 0" xyz="0 1 0"/>
    <parent link="base_link"/>
    <child link="right_wheel"/>
    <origin rpy="0 0 0" xyz="0.0 -0.1975 -0.0875"/>
  </joint>
  <link name="sick_link">
    <inertial>
      <mass value="1e-5"/>
      <origin xyz="0 0 0"/>
      <inertia ixx="1e-6" ixy="1e-20" ixz="1e-20" iyy="1e-6" iyz="1e-20" izz="1e-6"/>
    </inertial>
    <visual>
      <origin rpy="0 0 0" xyz="0 0 0"/>
      <geometry>
        <!-- Origin of this mesh is the focal point of the LIDAR. -->
        <mesh filename="package://lms1xx/meshes/sick-lms1xx.dae"/>
      </geometry>
    </visual>
    <!--collision>
        <origin xyz="0 0 -0.05" rpy="0 0 0" />
        <geometry>
          <box size="0.105 0.1 0.1" />
        </geometry>
      </collision-->
  </link>
  <gazebo reference="sick_link">
    <sensor name="sick_link" type="ray">
      <pose>0 0 0 0 0 0</pose>
      <visualize>false</visualize>
      <update_rate>50</update_rate>
      <ray>
        <scan>
          <horizontal>
            <samples>720</samples>
            <resolution>1</resolution>
            <min_angle>-1.57</min_angle>
            <max_angle>1.57</max_angle>
          </horizontal>
        </scan>
        <range>
          <min>0.1</min>
          <max>30.0</max>
          <resolution>0.01</resolution>
        </range>
        <noise>
          <type>gaussian</type>
          <mean>0.0</mean>
          <stddev>0.001</stddev>
        </noise>
      </ray>
      <plugin filename="libgazebo_ros_laser.so" name="gazebo_ros_laser">
        <topicName>scan</topicName>
        <frameName>sick_link</frameName>
        <robotNamespace>/</robotNamespace>
      </plugin>
    </sensor>
  </gazebo>
  <joint name="laser_joint" type="fixed">
    <origin rpy="0 0 0" xyz="0.317 0 0.13749999999999998"/>
    <parent link="base_link"/>
    <child link="sick_link"/>
  </joint>
  <joint name="dorso_head" type="fixed">
    <parent link="dorso_link"/>
    <child link="head_root"/>
    <origin rpy="0 0 0" xyz="0 0 0.8400000000000001"/>
  </joint>
  <!-- @TODO: GABIARRA PRA GIRAR A CAMERA -->
  <link name="head_pan_link_static">
    <inertial>
      <origin rpy="0 0 0" xyz="-1.35308431126191E-16 -2.97071395261028E-17 0.0220876265081744"/>
      <mass value="0.0182769203076134"/>
      <inertia ixx="1.32243845065555E-05" ixy="5.07660179129181E-13" ixz="1.067515220067E-20" iyy="7.13386116649085E-06" iyz="-1.32882457845217E-20" izz="7.83291781352837E-06"/>
    </inertial>
  </link>
  <link name="head_pan_link">
    <inertial>
      <origin rpy="0 0 0" xyz="-1.35308431126191E-16 -2.97071395261028E-17 0.0220876265081744"/>
      <mass value="0.0182769203076134"/>
      <inertia ixx="1.32243845065555E-05" ixy="5.07660179129181E-13" ixz="1.067515220067E-20" iyy="7.13386116649085E-06" iyz="-1.32882457845217E-20" izz="7.83291781352837E-06"/>
    </inertial>
    <visual>
      <origin rpy="0 0 0" xyz="0 0 0"/>
      <geometry>
        <mesh filename="package://doris_sensors_description/meshes/tilt_link.STL"/>
      </geometry>
      <material name="">
        <color rgba="0.250980392156863 0.250980392156863 0.250980392156863 1"/>
      </material>
    </visual>
    <collision>
      <origin rpy="0 0 0" xyz="0 0 0"/>
      <geometry>
        <mesh filename="package://doris_sensors_description/meshes/tilt_link.STL"/>
      </geometry>
    </collision>
  </link>
  <joint name="head_pan_joint_static" type="fixed">
    <origin rpy="0 0 0" xyz="0.07700000000000001 0 0.8"/>
    <parent link="dorso_link"/>
    <child link="head_pan_link_static"/>
    <axis xyz="0 0 1"/>
    <limit effort="1" lower="-1.57" upper="1.57" velocity="1"/>
  </joint>
  <joint name="head_pan_joint" type="revolute">
    <origin rpy="0 0 0" xyz="0.07700000000000001 0 0.8"/>
    <parent link="dorso_link"/>
    <child link="head_pan_link"/>
    <axis xyz="0 0 1"/>
    <limit effort="1" lower="-1.57" upper="1.57" velocity="1"/>
  </joint>
  <link name="head_tilt_link_static">
    <inertial>
      <origin rpy="0 0 0" xyz="0.0168744200088311 -0.000442984145897884 -0.00405256422002387"/>
      <mass value="0.0547677687275323"/>
      <inertia ixx="1.07071738005716E-05" ixy="-1.46854788384565E-07" ixz="5.59529059364376E-08" iyy="1.77011620295824E-05" iyz="1.27587154712834E-09" izz="2.01583693170578E-05"/>
    </inertial>
  </link>
  <link name="head_tilt_link">
    <inertial>
      <origin rpy="0 0 0" xyz="0.0168744200088311 -0.000442984145897884 -0.00405256422002387"/>
      <mass value="0.0547677687275323"/>
      <inertia ixx="1.07071738005716E-05" ixy="-1.46854788384565E-07" ixz="5.59529059364376E-08" iyy="1.77011620295824E-05" iyz="1.27587154712834E-09" izz="2.01583693170578E-05"/>
    </inertial>
    <visual>
      <origin rpy="0 0 0" xyz="0 0 0"/>
      <geometry>
        <mesh filename="package://doris_sensors_description/meshes/roll_link.STL"/>
      </geometry>
      <material name="">
        <color rgba="0.792156862745098 0.819607843137255 0.933333333333333 1"/>
      </material>
    </visual>
    <collision>
      <origin rpy="0 0 0" xyz="0 0 0"/>
      <geometry>
        <mesh filename="package://doris_sensors_description/meshes/roll_link.STL"/>
      </geometry>
    </collision>
  </link>
  <joint name="head_tilt_joint_static" type="fixed">
    <origin rpy="0 0 0" xyz="0 0 0.05"/>
    <parent link="head_pan_link_static"/>
    <child link="head_tilt_link_static"/>
    <axis xyz="0 1 0"/>
    <limit effort="1" lower="-1.57" upper="1.57" velocity="1"/>
  </joint>
  <joint name="head_tilt_joint" type="revolute">
    <origin rpy="0 0 0" xyz="0 0 0.05"/>
    <parent link="head_pan_link"/>
    <child link="head_tilt_link"/>
    <axis xyz="0 1 0"/>
    <limit effort="1" lower="-1.57" upper="1.57" velocity="1"/>
  </joint>
  <link name="camera_link_static">
    <inertial>
      <origin rpy="0 0 0" xyz="-0.0132722976093535 0.00168171470080143 2.49829664994428E-06"/>
      <mass value="0.0381925651163644"/>
      <inertia ixx="2.4688255642946E-05" ixy="1.60697655569215E-07" ixz="1.2993241737711E-08" iyy="3.66669176935806E-06" iyz="1.30215657011203E-08" izz="2.48602467766615E-05"/>
    </inertial>
  </link>
  <link name="camera_link">
    <inertial>
      <origin rpy="0 0 0" xyz="-0.0132722976093535 0.00168171470080143 2.49829664994428E-06"/>
      <mass value="0.0381925651163644"/>
      <inertia ixx="2.4688255642946E-05" ixy="1.60697655569215E-07" ixz="1.2993241737711E-08" iyy="3.66669176935806E-06" iyz="1.30215657011203E-08" izz="2.48602467766615E-05"/>
    </inertial>
    <visual>
      <origin rpy="0 0 0" xyz="0 0 0"/>
      <geometry>
        <mesh filename="package://doris_sensors_description/meshes/camera_link.STL"/>
      </geometry>
      <material name="">
        <color rgba="0.792156862745098 0.819607843137255 0.933333333333333 1"/>
      </material>
    </visual>
    <collision>
      <origin rpy="0 0 0" xyz="0 0 0"/>
      <geometry>
        <mesh filename="package://doris_sensors_description/meshes/camera_link.STL"/>
      </geometry>
    </collision>
  </link>
  <joint name="camera_joint_static" type="fixed">
    <origin rpy="0 0 0" xyz="0.06705 0 -0.00425"/>
    <parent link="head_tilt_link_static"/>
    <child link="camera_link_static"/>
    <axis xyz="0 0 0"/>
  </joint>
  <joint name="camera_joint" type="fixed">
    <origin rpy="0 0 0" xyz="0.06705 0 -0.00425"/>
    <parent link="head_tilt_link"/>
    <child link="camera_link"/>
    <axis xyz="0 0 0"/>
  </joint>
  <!-- <xacro:sensor_d435 parent="head_tilt_link" use_nominal_extrinsics="false" add_plug="false" use_mesh="true">
          <origin xyz="0.06705 0 -0.00425" rpy="0 0 0"/>
      </xacro:sensor_d435> -->
  <link name="left_front_caster_link">
    <visual>
      <material name="white"/>
      <geometry>
        <sphere radius="0.035"/>
      </geometry>
    </visual>
    <collision>
      <geometry>
        <sphere radius="0.035"/>
      </geometry>
    </collision>
  </link>
  <joint name="left_front_caster_joint" type="fixed">
    <origin rpy="0.0 0.0 0.0" xyz="0.215 0.1325 -0.1525"/>
    <parent link="base_link"/>
    <child link="left_front_caster_link"/>
  </joint>
  <link name="right_front_caster_link">
    <visual>
      <material name="white"/>
      <geometry>
        <sphere radius="0.035"/>
      </geometry>
    </visual>
    <collision>
      <geometry>
        <sphere radius="0.035"/>
      </geometry>
    </collision>
  </link>
  <joint name="right_front_caster_joint" type="fixed">
    <origin rpy="0.0 0.0 0.0" xyz="0.215 -0.1325 -0.1525"/>
    <parent link="base_link"/>
    <child link="right_front_caster_link"/>
  </joint>
  <link name="left_back_caster_link">
    <visual>
      <material name="white"/>
      <geometry>
        <sphere radius="0.035"/>
      </geometry>
    </visual>
    <collision>
      <geometry>
        <sphere radius="0.035"/>
      </geometry>
    </collision>
  </link>
  <joint name="left_back_caster_joint" type="fixed">
    <origin rpy="0.0 0.0 0.0" xyz="-0.215 0.1325 -0.1525"/>
    <parent link="base_link"/>
    <child link="left_back_caster_link"/>
  </joint>
  <link name="right_back_caster_link">
    <visual>
      <material name="white"/>
      <geometry>
        <sphere radius="0.035"/>
      </geometry>
    </visual>
    <collision>
      <geometry>
        <sphere radius="0.035"/>
      </geometry>
    </collision>
  </link>
  <joint name="right_back_caster_joint" type="fixed">
    <origin rpy="0.0 0.0 0.0" xyz="-0.215 -0.1325 -0.1525"/>
    <parent link="base_link"/>
    <child link="right_back_caster_link"/>
  </joint>
  <link name="dorso_link">
    <inertial>
      <mass value="1"/>
      <inertia ixx="0.053341666666666676" ixy="0.0" ixz="0.0" iyy="0.06279741666666667" iyz="0.0" izz="0.009472416666666667"/>
    </inertial>
    <visual>
      <origin xyz="0.0 0.0 0.4"/>
      <material name="lightgray"/>
      <geometry>
        <box size="0.28 0.337 0.8"/>
      </geometry>
    </visual>
    <collision>
      <origin xyz="0.0 0.0 0.4"/>
      <geometry>
        <box size="0.28 0.337 0.8"/>
      </geometry>
    </collision>
  </link>
  <joint name="dorso_joint" type="fixed">
    <parent link="base_link"/>
    <child link="dorso_link"/>
    <origin rpy="0 0 0" xyz="-0.10999999999999999 0 0.1175"/>
  </joint>
  0
  
  <link name="arm_support_link">
    <inertial>
      <mass value="1"/>
      <inertia ixx="0.00014166666666666668" ixy="0.0" ixz="0.0" iyy="0.009766666666666668" iyz="0.0" izz="0.009641666666666668"/>
    </inertial>
    <visual>
      <material name="lightgray"/>
      <geometry>
        <box size="0.33 0.34 0.04"/>
      </geometry>
    </visual>
    <collision>
      <geometry>
        <box size="0.33 0.34 0.04"/>
      </geometry>
    </collision>
  </link>
  <joint name="arm_support_joint" type="fixed">
    <parent link="dorso_link"/>
    <child link="arm_support_link"/>
    
        CTRL-C to quit
        
        
    <origin rpy="0 0 0" xyz="0.30500000000000005 0 0.51"/>
  </joint>
  <link name="hokuyo_ground_link">
    <!--collision>
        <origin xyz="0 0 0" rpy="0 0 0"/>
        <geometry>
          <box size="0.01 0.01 0.01"/>
        </geometry>
      </collision-->
    <visual>
      <origin rpy="0 0 0" xyz="0 0 0"/>
      <geometry>
        <mesh filename="package://doris_sensors_description/meshes/sensors/hokuyo.dae"/>
      </geometry>
    </visual>
    <inertial>
      <mass value="1e-5"/>
      <origin rpy="0 0 0" xyz="0 0 0"/>
      <inertia ixx="1e-6" ixy="0" ixz="0" iyy="1e-6" iyz="0" izz="1e-6"/>
    </inertial>
  </link>
  <joint name="hokuyo_ground_joint" type="fixed">
    <!--<axis xyz="0 0 1" />-->
    <origin rpy="3.14 0 0" xyz="0.29100000000000004 0 -0.09749999999999999"/>
    <parent link="base_link"/>
    <child link="hokuyo_ground_link"/>
  </joint>
  <gazebo reference="hokuyo_ground_link">
    <sensor name="head_hokuyo_ground_sensor" type="ray">
      <pose>0 0 0 0 0 0</pose>
      <visualize>false</visualize>
      <update_rate>40</update_rate>
      <ray>
        <scan>
          <horizontal>
            <samples>683</samples>
            <resolution>0.3515625</resolution>
            <min_angle>-2.0943</min_angle>
            <max_angle>2.0943</max_angle>
          </horizontal>
        </scan>
        <range>
          <min>0.15</min>
          <max>4.0</max>
          <resolution>0.01</resolution>
        </range>
        <noise>
          <type>gaussian</type>
          <!-- Noise parameters based on published spec for Hokuyo laser
               achieving "+-30mm" accuracy at range < 10m.  A mean of 0.0m and
               stddev of 0.01m will put 99.7% of samples within 0.03m of the true
               reading. -->
          <mean>0.0</mean>
          <stddev>0.01</stddev>
        </noise>
      </ray>
      <plugin filename="libgazebo_ros_laser.so" name="gazebo_ros_head_hokuyo_controller">
        <topicName>/scan2</topicName>
        <frameName>hokuyo_ground_link</frameName>
        <robotNamespace>/</robotNamespace>
      </plugin>
    </sensor>
  </gazebo>
  <link name="hokuyo_back_link">
    <!--collision>
        <origin xyz="0 0 0" rpy="0 0 0"/>
        <geometry>
          <box size="0.01 0.01 0.01"/>
        </geometry>
      </collision-->
    <visual>
      <origin rpy="0 0 0" xyz="0 0 0"/>
      <geometry>
        <mesh filename="package://doris_sensors_description/meshes/sensors/hokuyo.dae"/>
      </geometry>
    </visual>
    <inertial>
      <mass value="1e-5"/>
      <origin rpy="0 0 0" xyz="0 0 0"/>
      <inertia ixx="1e-6" ixy="0" ixz="0" iyy="1e-6" iyz="0" izz="1e-6"/>
    </inertial>
  </link>
  <joint name="hokuyo_back_joint" type="fixed">
    <!--<axis xyz="0 0 1" />-->
    <origin rpy="3.14 0 3.14" xyz="-0.29100000000000004 0 -0.09749999999999999"/>
    <parent link="base_link"/>
    <child link="hokuyo_back_link"/>
  </joint>
  <gazebo reference="hokuyo_back_link">
    <sensor name="head_hokuyo_back_sensor" type="ray">
      <pose>0 0 0 0 0 0</pose>
      <visualize>false</visualize>
      <update_rate>40</update_rate>
      <ray>
        <scan>
          <horizontal>
            <samples>683</samples>
            <resolution>0.3515625</resolution>
            <min_angle>-2.0943</min_angle>
            <max_angle>2.0943</max_angle>
          </horizontal>
        </scan>
        <range>
          <min>0.15</min>
          <max>4.0</max>
          <resolution>0.01</resolution>
        </range>
        <noise>
          <type>gaussian</type>
          <!-- Noise parameters based on published spec for Hokuyo laser
               achieving "+-30mm" accuracy at range < 10m.  A mean of 0.0m and
               stddev of 0.01m will put 99.7% of samples within 0.03m of the true
               reading. -->
          <mean>0.0</mean>
          <stddev>0.01</stddev>
        </noise>
      </ray>
      <plugin filename="libgazebo_ros_laser.so" name="gazebo_ros_head_hokuyo_controller">
        <topicName>/scan3</topicName>
        <frameName>hokuyo_back_link</frameName>
        <robotNamespace>/</robotNamespace>
      </plugin>
    </sensor>
  </gazebo>
  <link name="imu_link"/>
  <joint name="imu_joint" type="fixed">
    <parent link="base_link"/>
    <child link="imu_link"/>
    <origin rpy="0 0 0" xyz="0.3125 0 -0.09749999999999999"/>
  </joint>
  <material name="interbotix_black">
    <texture filename="package://interbotix_xsarm_descriptions/meshes/interbotix_black.png"/>
  </material>
  <joint name="arm_arm_support_link_joint" type="fixed">
    <origin rpy="0 0 0" xyz="0.1 0 0.02"/>
    <parent link="arm_support_link"/>
    <child link="boris_arm/base_link"/>
  </joint>
  <link name="boris_arm/base_link">
    <visual>
      <origin rpy="1.5707963267948966 0 1.5707963267948966" xyz="-0.095773 0 -0.10565023"/>
      <geometry>
        <mesh filename="package://interbotix_xsarm_descriptions/meshes/mobile_wx200_meshes/mobile_wx200_1_base.stl" scale="0.001 0.001 0.001"/>
      </geometry>
      <material name="interbotix_black"/>
    </visual>
    <collision>
      <origin rpy="1.5707963267948966 0 1.5707963267948966" xyz="-0.095773 0 -0.10565023"/>
      <geometry>
        <mesh filename="package://interbotix_xsarm_descriptions/meshes/mobile_wx200_meshes/mobile_wx200_1_base.stl" scale="0.001 0.001 0.001"/>
      </geometry>
    </collision>
    <inertial>
      <origin rpy="1.5707963267948966 0 1.5707963267948966" xyz="-0.0001350000 -0.0000266286 0.0338755000"/>
      <mass value="0.379673"/>
      <inertia ixx="0.0004351000" ixy="0.0000000707" ixz="0.0000000266" iyy="0.0004452000" iyz="-0.0000022881" izz="0.0005731000"/>
    </inertial>
  </link>
  <joint name="waist" type="revolute">
    <axis xyz="0 0 1"/>
    <limit effort="8" lower="-3.141582653589793" upper="3.141582653589793" velocity="3.141592653589793"/>
    <origin rpy="0 0 0" xyz="0 0 0.066175"/>
    <parent link="boris_arm/base_link"/>
    <child link="boris_arm/shoulder_link"/>
    <dynamics friction="0.1"/>
  </joint>
  <transmission name="trans_waist">
    <type>transmission_interface/SimpleTransmission</type>
    <joint name="waist">
      <hardwareInterface>hardware_interface/EffortJointInterface</hardwareInterface>
    </joint>
    <actuator name="waist_motor">
      <mechanicalReduction>1</mechanicalReduction>
    </actuator>
  </transmission>
  <link name="boris_arm/shoulder_link">
    <visual>
      <origin rpy="0 0 1.5707963267948966" xyz="0 0 -0.003"/>
      <geometry>
        <mesh filename="package://interbotix_xsarm_descriptions/meshes/mobile_wx200_meshes/mobile_wx200_2_shoulder.stl" scale="0.001 0.001 0.001"/>
      </geometry>
      <material name="interbotix_black"/>
    </visual>
    <collision>
      <origin rpy="0 0 1.5707963267948966" xyz="0 0 -0.003"/>
      <geometry>
        <mesh filename="package://interbotix_xsarm_descriptions/meshes/mobile_wx200_meshes/mobile_wx200_2_shoulder.stl" scale="0.001 0.001 0.001"/>
      </geometry>
    </collision>
    <inertial>
      <origin rpy="0 0 1.5707963267948966" xyz="0.0000223210 0.0000414608 0.0066287000"/>
      <mass value="0.480879"/>
      <inertia ixx="0.0003790000" ixy="0.0000000022" ixz="-0.0000003561" iyy="0.0005557000" iyz="0.0000012247" izz="0.0005889000"/>
    </inertial>
  </link>
  <joint name="shoulder" type="revolute">
    <axis xyz="0 1 0"/>
    <limit effort="18" lower="-1.8849555921538759" upper="1.9722220547535925" velocity="3.141592653589793"/>
    <origin rpy="0 0 0" xyz="0 0 0.03865"/>
    <parent link="boris_arm/shoulder_link"/>
    <child link="boris_arm/upper_arm_link"/>
    <dynamics friction="0.1"/>
  </joint>
  <transmission name="trans_shoulder">
    <type>transmission_interface/SimpleTransmission</type>
    <joint name="shoulder">
      <hardwareInterface>hardware_interface/EffortJointInterface</hardwareInterface>
    </joint>
    <actuator name="shoulder_motor">
      <mechanicalReduction>1</mechanicalReduction>
    </actuator>
  </transmission>
  <link name="boris_arm/upper_arm_link">
    <visual>
      <origin rpy="0 0 1.5707963267948966" xyz="0 0 0"/>
      <geometry>
        <mesh filename="package://interbotix_xsarm_descriptions/meshes/mobile_wx200_meshes/mobile_wx200_3_upper_arm.stl" scale="0.001 0.001 0.001"/>
      </geometry>
      <material name="interbotix_black"/>
    </visual>
    <collision>
      <origin rpy="0 0 1.5707963267948966" xyz="0 0 0"/>
      <geometry>
        <mesh filename="package://interbotix_xsarm_descriptions/meshes/mobile_wx200_meshes/mobile_wx200_3_upper_arm.stl" scale="0.001 0.001 0.001"/>
      </geometry>
    </collision>
    <inertial>
      <origin rpy="0 0 1.5707963267948966" xyz="0.0119707000 -0.0001179264 0.1394290000"/>
      <mass value="0.297781"/>
      <inertia ixx="0.0017100000" ixy="-0.0000011433" ixz="0.0000021161" iyy="0.0016310000" iyz="0.0002135000" izz="0.0001482000"/>
    </inertial>
  </link>
  <joint name="elbow" type="revolute">
    <axis xyz="0 1 0"/>
    <limit effort="13" lower="-1.8849555921538759" upper="1.6231562043547265" velocity="3.141592653589793"/>
    <origin rpy="0 0 0" xyz="0.05 0 0.2"/>
    <parent link="boris_arm/upper_arm_link"/>
    <child link="boris_arm/forearm_link"/>
    <dynamics friction="0.1"/>
  </joint>
  <transmission name="trans_elbow">
    <type>transmission_interface/SimpleTransmission</type>
    <joint name="elbow">
      <hardwareInterface>hardware_interface/EffortJointInterface</hardwareInterface>
    </joint>
    <actuator name="elbow_motor">
      <mechanicalReduction>1</mechanicalReduction>
    </actuator>
  </transmission>
  <link name="boris_arm/forearm_link">
    <visual>
      <origin rpy="0 0 1.5707963267948966" xyz="0 0 0"/>
      <geometry>
        <mesh filename="package://interbotix_xsarm_descriptions/meshes/mobile_wx200_meshes/mobile_wx200_4_forearm.stl" scale="0.001 0.001 0.001"/>
      </geometry>
      <material name="interbotix_black"/>
    </visual>
    <collision>
      <origin rpy="0 0 1.5707963267948966" xyz="0 0 0"/>
      <geometry>
        <mesh filename="package://interbotix_xsarm_descriptions/meshes/mobile_wx200_meshes/mobile_wx200_4_forearm.stl" scale="0.001 0.001 0.001"/>
      </geometry>
    </collision>
    <inertial>
      <origin rpy="0 0 1.5707963267948966" xyz="0.1211920000 -0.0001238123 0.0000000000"/>
      <mass value="0.283651"/>
      <inertia ixx="0.0011850000" ixy="-0.0000024317" ixz="0.0000000000" iyy="0.0000682900" iyz="0.0000000000" izz="0.0012060000"/>
    </inertial>
  </link>
  <joint name="wrist_angle" type="revolute">
    <axis xyz="0 1 0"/>
    <limit effort="5" lower="-1.7453292519943295" upper="2.1467549799530254" velocity="3.141592653589793"/>
    <origin rpy="0 0 0" xyz="0.2 0 0"/>
    <parent link="boris_arm/forearm_link"/>
    <child link="boris_arm/wrist_link"/>
    <dynamics friction="0.1"/>
  </joint>
  <transmission name="trans_wrist_angle">
    <type>transmission_interface/SimpleTransmission</type>
    <joint name="wrist_angle">
      <hardwareInterface>hardware_interface/EffortJointInterface</hardwareInterface>
    </joint>
    <actuator name="wrist_angle_motor">
      <mechanicalReduction>1</mechanicalReduction>
    </actuator>
  </transmission>
  <link name="boris_arm/wrist_link">
    <visual>
      <origin rpy="0 0 1.5707963267948966" xyz="0 0 0"/>
      <geometry>
        <mesh filename="package://interbotix_xsarm_descriptions/meshes/mobile_wx200_meshes/mobile_wx200_5_wrist.stl" scale="0.001 0.001 0.001"/>
      </geometry>
      <material name="interbotix_black"/>
    </visual>
    <collision>
      <origin rpy="0 0 1.5707963267948966" xyz="0 0 0"/>
      <geometry>
        <mesh filename="package://interbotix_xsarm_descriptions/meshes/mobile_wx200_meshes/mobile_wx200_5_wrist.stl" scale="0.001 0.001 0.001"/>
      </geometry>
    </collision>
    <inertial>
      <origin rpy="0 0 1.5707963267948966" xyz="0.0423600000 -0.0000106630 0.0105770000"/>
      <mass value="0.084957"/>
      <inertia ixx="0.0000308200" ixy="0.0000000191" ixz="0.0000000023" iyy="0.0000282200" iyz="0.0000025481" izz="0.0000315200"/>
    </inertial>
  </link>
  <joint name="wrist_rotate" type="revolute">
    <axis xyz="1 0 0"/>
    <limit effort="1" lower="-3.141582653589793" upper="3.141582653589793" velocity="3.141592653589793"/>
    <origin rpy="0 0 0" xyz="0.065 0 0"/>
    <parent link="boris_arm/wrist_link"/>
    <child link="boris_arm/gripper_link"/>
    <dynamics friction="0.1"/>
  </joint>
  <transmission name="trans_wrist_rotate">
    <type>transmission_interface/SimpleTransmission</type>
    <joint name="wrist_rotate">
      <hardwareInterface>hardware_interface/EffortJointInterface</hardwareInterface>
    </joint>
    <actuator name="wrist_rotate_motor">
      <mechanicalReduction>1</mechanicalReduction>
    </actuator>
  </transmission>
  <link name="boris_arm/gripper_link">
    <visual>
      <origin rpy="0 0 1.5707963267948966" xyz="-0.02 0 0"/>
      <geometry>
        <mesh filename="package://interbotix_xsarm_descriptions/meshes/mobile_wx200_meshes/mobile_wx200_6_gripper.stl" scale="0.001 0.001 0.001"/>
      </geometry>
      <material name="interbotix_black"/>
    </visual>
    <collision>
      <origin rpy="0 0 1.5707963267948966" xyz="-0.02 0 0"/>
      <geometry>
        <mesh filename="package://interbotix_xsarm_descriptions/meshes/mobile_wx200_meshes/mobile_wx200_6_gripper.stl" scale="0.001 0.001 0.001"/>
      </geometry>
    </collision>
    <inertial>
      <origin rpy="0 0 1.5707963267948966" xyz="0.0216310000 0.0000002516 0.0114100000"/>
      <mass value="0.072885"/>
      <inertia ixx="0.0000253700" ixy="0.0000000000" ixz="0.0000000000" iyy="0.0000183600" iyz="0.0000004340" izz="0.0000167400"/>
    </inertial>
  </link>
  <joint name="ee_arm" type="fixed">
    <axis xyz="1 0 0"/>
    <origin rpy="0 0 0" xyz="0.043 0 0"/>
    <parent link="boris_arm/gripper_link"/>
    <child link="boris_arm/ee_arm_link"/>
  </joint>
  <link name="boris_arm/ee_arm_link">
    <inertial>
      <mass value="0.001"/>
      <inertia ixx="0.001" ixy="0" ixz="0" iyy="0.001" iyz="0" izz="0.001"/>
    </inertial>
  </link>
  <joint name="gripper" type="continuous">
    <axis xyz="1 0 0"/>
    <limit effort="1" velocity="3.141592653589793"/>
    <origin rpy="0 0 0" xyz="0.0055 0 0"/>
    <parent link="boris_arm/ee_arm_link"/>
    <child link="boris_arm/gripper_prop_link"/>
    <dynamics friction="0.1"/>
  </joint>
  <transmission name="trans_gripper">
    <type>transmission_interface/SimpleTransmission</type>
    <joint name="gripper">
      <hardwareInterface>hardware_interface/EffortJointInterface</hardwareInterface>
    </joint>
    <actuator name="gripper_motor">
      <mechanicalReduction>1</mechanicalReduction>
    </actuator>
  </transmission>
  <link name="boris_arm/gripper_prop_link">
    <visual>
      <origin rpy="0 0 1.5707963267948966" xyz="-0.0685 0 0"/>
      <geometry>
        <mesh filename="package://interbotix_xsarm_descriptions/meshes/mobile_wx200_meshes/mobile_wx200_7_gripper_prop.stl" scale="0.001 0.001 0.001"/>
      </geometry>
      <material name="interbotix_black"/>
    </visual>
    <collision>
      <origin rpy="0 0 1.5707963267948966" xyz="-0.0685 0 0"/>
      <geometry>
        <mesh filename="package://interbotix_xsarm_descriptions/meshes/mobile_wx200_meshes/mobile_wx200_7_gripper_prop.stl" scale="0.001 0.001 0.001"/>
      </geometry>
    </collision>
    <inertial>
      <origin rpy="0 0 1.5707963267948966" xyz="0.0008460000 -0.0000016817 0.0000420000"/>
      <mass value="0.00434"/>
      <inertia ixx="0.0000005923" ixy="0.0000000000" ixz="0.0000003195" iyy="0.0000011156" iyz="-0.0000000004" izz="0.0000005743"/>
    </inertial>
  </link>
  <!-- If the AR tag is being used, then add the AR tag mount -->
  <!-- If the gripper bar is being used, then also add the gripper bar -->
  <joint name="gripper_bar" type="fixed">
    <axis xyz="1 0 0"/>
    <origin rpy="0 0 0" xyz="0 0 0"/>
    <parent link="boris_arm/ee_arm_link"/>
    <child link="boris_arm/gripper_bar_link"/>
  </joint>
  <link name="boris_arm/gripper_bar_link">
    <visual>
      <origin rpy="0 0 1.5707963267948966" xyz="-0.063 0 0"/>
      <geometry>
        <mesh filename="package://interbotix_xsarm_descriptions/meshes/mobile_wx200_meshes/mobile_wx200_8_gripper_bar.stl" scale="0.001 0.001 0.001"/>
      </geometry>
      <material name="interbotix_black"/>
    </visual>
    <collision>
      <origin rpy="0 0 1.5707963267948966" xyz="-0.063 0 0"/>
      <geometry>
        <mesh filename="package://interbotix_xsarm_descriptions/meshes/mobile_wx200_meshes/mobile_wx200_8_gripper_bar.stl" scale="0.001 0.001 0.001"/>
      </geometry>
    </collision>
    <inertial>
      <origin rpy="0 0 1.5707963267948966" xyz="0.0096870000 0.0000008177 0.0049620000"/>
      <mass value="0.034199"/>
      <inertia ixx="0.0000074125" ixy="-0.0000000008" ixz="-0.0000000006" iyy="0.0000284300" iyz="-0.0000013889" izz="0.0000286000"/>
    </inertial>
  </link>
  <joint name="ee_bar" type="fixed">
    <axis xyz="1 0 0"/>
    <origin rpy="0 0 0" xyz="0.023 0 0"/>
    <parent link="boris_arm/gripper_bar_link"/>
    <child link="boris_arm/fingers_link"/>
  </joint>
  <link name="boris_arm/fingers_link">
    <inertial>
      <mass value="0.001"/>
      <inertia ixx="0.001" ixy="0" ixz="0" iyy="0.001" iyz="0" izz="0.001"/>
    </inertial>
  </link>
  <!-- If the gripper fingers are being used, add those as well -->
  <joint name="left_finger" type="prismatic">
    <axis xyz="0 1 0"/>
    <limit effort="5" lower="0.015" upper="0.037" velocity="1"/>
    <origin rpy="0 0 0" xyz="0 0 0"/>
    <parent link="boris_arm/fingers_link"/>
    <child link="boris_arm/left_finger_link"/>
    <dynamics friction="0.1"/>
  </joint>
  <transmission name="trans_left_finger">
    <type>transmission_interface/SimpleTransmission</type>
    <joint name="left_finger">
      <hardwareInterface>hardware_interface/EffortJointInterface</hardwareInterface>
    </joint>
    <actuator name="left_finger_motor">
      <mechanicalReduction>1</mechanicalReduction>
    </actuator>
  </transmission>
  <link name="boris_arm/left_finger_link">
    <visual>
      <origin rpy="3.141592653589793 3.141592653589793 0" xyz="0 0.005 0"/>
      <geometry>
        <mesh filename="package://interbotix_xsarm_descriptions/meshes/mobile_wx200_meshes/mobile_wx200_9_gripper_finger.stl" scale="0.001 0.001 0.001"/>
      </geometry>
      <material name="interbotix_black"/>
    </visual>
    <collision>
      <origin rpy="3.141592653589793 3.141592653589793 0" xyz="0 0.005 0"/>
      <geometry>
        <mesh filename="package://interbotix_xsarm_descriptions/meshes/mobile_wx200_meshes/mobile_wx200_9_gripper_finger.stl" scale="0.001 0.001 0.001"/>
      </geometry>
    </collision>
    <inertial>
      <origin rpy="3.141592653589793 3.141592653589793 1.5707963267948966" xyz="0.0138160000 0.0000000000 0.0000000000"/>
      <mass value="0.016246"/>
      <inertia ixx="0.0000047310" ixy="-0.0000004560" ixz="0.0000000000" iyy="0.0000015506" iyz="0.0000000000" izz="0.0000037467"/>
    </inertial>
  </link>
  <joint name="right_finger" type="prismatic">
    <axis xyz="0 1 0"/>
    <limit effort="5" lower="-0.037" upper="-0.015" velocity="1"/>
    <origin rpy="0 0 0" xyz="0 0 0"/>
    <parent link="boris_arm/fingers_link"/>
    <child link="boris_arm/right_finger_link"/>
    <dynamics friction="0.1"/>
    <mimic joint="left_finger" multiplier="-1" offset="0"/>
  </joint>
  <transmission name="trans_right_finger">
    <type>transmission_interface/SimpleTransmission</type>
    <joint name="right_finger">
      <hardwareInterface>hardware_interface/EffortJointInterface</hardwareInterface>
    </joint>
    <actuator name="right_finger_motor">
      <mechanicalReduction>1</mechanicalReduction>
    </actuator>
  </transmission>
  <link name="boris_arm/right_finger_link">
    <visual>
      <origin rpy="0 3.141592653589793 0" xyz="0 -0.005 0"/>
      <geometry>
        <mesh filename="package://interbotix_xsarm_descriptions/meshes/mobile_wx200_meshes/mobile_wx200_9_gripper_finger.stl" scale="0.001 0.001 0.001"/>
      </geometry>
      <material name="interbotix_black"/>
    </visual>
    <collision>
      <origin rpy="0 3.141592653589793 0" xyz="0 -0.005 0"/>
      <geometry>
        <mesh filename="package://interbotix_xsarm_descriptions/meshes/mobile_wx200_meshes/mobile_wx200_9_gripper_finger.stl" scale="0.001 0.001 0.001"/>
      </geometry>
    </collision>
    <inertial>
      <origin rpy="0 3.141592653589793 1.5707963267948966" xyz="0.0138160000 0.0000000000  0.0000000000"/>
      <mass value="0.016246"/>
      <inertia ixx="0.0000047310" ixy="0.0000004560" ixz="0.0000000000" iyy="0.0000015506" iyz="0.0000000000" izz="0.0000037467"/>
    </inertial>
  </link>
  <joint name="ee_gripper" type="fixed">
    <axis xyz="1 0 0"/>
    <origin rpy="0 0 0" xyz="0.027575 0 0"/>
    <parent link="boris_arm/fingers_link"/>
    <child link="boris_arm/ee_gripper_link"/>
  </joint>
  <link name="boris_arm/ee_gripper_link">
    <inertial>
      <mass value="0.001"/>
      <inertia ixx="0.001" ixy="0" ixz="0" iyy="0.001" iyz="0" izz="0.001"/>
    </inertial>
  </link>
  <gazebo reference="left_back_caster">
    <mu1 value="0.0"/>
    <mu2 value="0.0"/>
  </gazebo>
  <gazebo reference="left_front_caster">
    <mu1 value="0.0"/>
    <mu2 value="0.0"/>
  </gazebo>
  <gazebo reference="right_front_caster">
    <mu1 value="0.0"/>
    <mu2 value="0.0"/>
  </gazebo>
  <gazebo reference="right_back_caster">
    <mu1 value="0.0"/>
    <mu2 value="0.0"/>
  </gazebo>
</robot>
